<?xml version="1.0" ?>
<robot name="gtu_arm_simple" xmlns:xacro="http://www.ros.org/wiki/xacro">

<xacro:include filename="$(find gtu_arm_simple_description)/urdf/materials.xacro" />
<xacro:include filename="$(find gtu_arm_simple_description)/urdf/gtu_arm_simple.trans" />
<xacro:include filename="$(find gtu_arm_simple_description)/urdf/gtu_arm_simple.gazebo" />
<link name="base_link">
  <inertial>
    <origin rpy="0 0 0" xyz="-0.0003 -0.0 0.0620"/>
    <mass value="4.6095"/>
    <inertia ixx="0.0098" ixy="0.0" ixz="-0.0" iyy="0.0064" iyz="0.0" izz="0.01454"/>
  </inertial>
  <visual>
    <origin rpy="0 0 0" xyz="0 0 0"/>
    <geometry>
      <mesh filename="package://gtu_arm_simple_description/meshes/base_link.stl"/>
    </geometry>
    <material name="silver"/>
  </visual>
  <collision>
    <origin rpy="0 0 0" xyz="0 0 0"/>
    <geometry>
      <mesh filename="package://gtu_arm_simple_description/meshes/base_link.stl"/>
    </geometry>
  </collision>
</link>

<link name="link1">
  <inertial>
    <origin rpy="0 0 0" xyz="-0.0003 0.0414 0.0140"/>
    <mass value="5.6966"/>
    <inertia ixx="0.0205" ixy="-0.0" ixz="-0.0001" iyy="0.0259" iyz="-0.0012" izz="0.0429"/>
  </inertial>
  <visual>
    <origin rpy="0 0 0" xyz="0.0005 0.0 -0.095"/>
    <geometry>
      <mesh filename="package://gtu_arm_simple_description/meshes/link1.stl"/>
    </geometry>
    <material name="silver"/>
  </visual>
  <collision>
    <origin rpy="0 0 0" xyz="0.0005 0.0 -0.095"/>
    <geometry>
      <mesh filename="package://gtu_arm_simple_description/meshes/link1.stl"/>
    </geometry>
  </collision>
</link>

<link name="link2">
  <inertial>
    <origin rpy="0 0 0" xyz="-0.0011 -0.0102 0.2446"/>
    <mass value="6.3034"/>
    <inertia ixx="0.1301" ixy="-0.0" ixz="0.0003" iyy="0.1119" iyz="0.0241" izz="0.0384"/>
  </inertial>
  <visual>
    <origin rpy="0 0 0" xyz="0.0001 -0.064 -0.144"/>
    <geometry>
      <mesh filename="package://gtu_arm_simple_description/meshes/link2.stl"/>
    </geometry>
    <material name="silver"/>
  </visual>
  <collision>
    <origin rpy="0 0 0" xyz="0.001 -0.064 -0.144"/>
    <geometry>
      <mesh filename="package://gtu_arm_simple_description/meshes/link2.stl"/>
    </geometry>
  </collision>
</link>

<link name="link3">
  <inertial>
    <origin rpy="0 0 0" xyz="0.0002 -0.0607 0.0127"/>
    <mass value="2.4044"/>
    <inertia ixx="0.0165" ixy="0.0" ixz="0.0" iyy="0.0044" iyz="-0.0028" izz="0.0164"/>
  </inertial>
  <visual>
    <origin rpy="0 0 0" xyz="0.0024 0.0797 -0.5865"/>
    <geometry>
      <mesh filename="package://gtu_arm_simple_description/meshes/link3.stl"/>
    </geometry>
    <material name="silver"/>
  </visual>
  <collision>
    <origin rpy="0 0 0" xyz="0.0024 0.0797 -0.5865"/>
    <geometry>
      <mesh filename="package://gtu_arm_simple_description/meshes/link3.stl"/>
    </geometry>
  </collision>
</link>

<link name="link4">
  <inertial>
    <origin rpy="0 0 0" xyz="0.0004 -0.0779 0.0"/>
    <mass value="1.4724"/>
    <inertia ixx="0.0052" ixy="0.0" ixz="-0.0" iyy="0.0019" iyz="0.0" izz="0.0059"/>
  </inertial>
  <visual>
    <origin rpy="0 0 0" xyz="0.0016 0.2627 -0.5865"/>
    <geometry>
      <mesh filename="package://gtu_arm_simple_description/meshes/link4.stl"/>
    </geometry>
    <material name="silver"/>
  </visual>
  <collision>
    <origin rpy="0 0 0" xyz="0.0016 0.2627 -0.5865"/>
    <geometry>
      <mesh filename="package://gtu_arm_simple_description/meshes/link4.stl"/>
    </geometry>
  </collision>
</link>

<link name="link5">
  <inertial>
    <origin rpy="0 0 0" xyz="0.0114 0.0 -0.058"/>
    <mass value="2.2806"/>
    <inertia ixx="0.0112" ixy="-0.0" ixz="-0.0014" iyy="0.0139" iyz="-0.0" izz="0.004"/>
  </inertial>
  <visual>
    <origin rpy="0 0 0" xyz="0.0008 0.4142 -0.5865"/>
    <geometry>
      <mesh filename="package://gtu_arm_simple_description/meshes/link5.stl"/>
    </geometry>
    <material name="silver"/>
  </visual>
  <collision>
    <origin rpy="0 0 0" xyz="0.0008 0.4142 -0.5865"/>
    <geometry>
      <mesh filename="package://gtu_arm_simple_description/meshes/link5.stl"/>
    </geometry>
  </collision>
</link>

<link name="hand">
  <inertial>
    <origin rpy="0 0 0" xyz="0.0 0.0003 -0.0367"/>
    <mass value="0.5769"/>
    <inertia ixx="0.0003" ixy="0.0" ixz="-0.0" iyy="0.0004" iyz="0.0" izz="0.0002"/>
  </inertial>
  <visual>
    <origin rpy="0 0 0" xyz="0.0 0.4142 -0.413"/>
    <geometry>
      <mesh filename="package://gtu_arm_simple_description/meshes/hand.stl"/>
    </geometry>
    <material name="silver"/>
  </visual>
  <collision>
    <origin rpy="0 0 0" xyz="0.0 0.4142 -0.413"/>
    <geometry>
      <mesh filename="package://gtu_arm_simple_description/meshes/hand.stl"/>
    </geometry>
  </collision>
</link>

<link name="finger_r">
  <inertial>
    <origin rpy="0 0 0" xyz="-0.0033 0.0035 -0.0598"/>
    <mass value="0.3811"/>
    <inertia ixx="0.0004" ixy="-0.0" ixz="-0.0" iyy="0.0004" iyz="-0.0" izz="0.0"/>
  </inertial>
  <visual>
    <origin rpy="0 0 0" xyz="0.0137 0.4177 -0.3521"/>
    <geometry>
      <mesh filename="package://gtu_arm_simple_description/meshes/finger_r.stl"/>
    </geometry>
    <material name="silver"/>
  </visual>
  <collision>
    <origin rpy="0 0 0" xyz="0.0137 0.4177 -0.3521"/>
    <geometry>
      <mesh filename="package://gtu_arm_simple_description/meshes/finger_r.stl"/>
    </geometry>
  </collision>
</link>

<link name="finger_l">
  <inertial>
    <origin rpy="0 0 0" xyz="0.0039 0.0036 -0.0595"/>
    <mass value="0.383"/>
    <inertia ixx="0.0004" ixy="0.0" ixz="0.0" iyy="0.0004" iyz="-0.0" izz="0.0"/>
  </inertial>
  <visual>
    <origin rpy="0 0 0" xyz="-0.0143 0.4176 -0.3523"/>
    <geometry>
      <mesh filename="package://gtu_arm_simple_description/meshes/finger_l.stl"/>
    </geometry>
    <material name="silver"/>
  </visual>
  <collision>
    <origin rpy="0 0 0" xyz="-0.0143 0.4176 -0.3522"/>
    <geometry>
      <mesh filename="package://gtu_arm_simple_description/meshes/finger_l.stl"/>
    </geometry>
  </collision>
</link>

<joint name="Rev1" type="continuous">
  <origin rpy="0 0 0" xyz="-0.0005 0.0 0.095"/>
  <parent link="base_link"/>
  <child link="link1"/>
  <axis xyz="-0.0048 0.0 1.0"/>
</joint>

<joint name="Rev2" type="continuous">
  <origin rpy="0 0 0" xyz="-0.0005 0.064 0.049"/>
  <parent link="link1"/>
  <child link="link2"/>
  <axis xyz="-1.0 -0.0048 -0.0048"/>
</joint>

<joint name="Rev3" type="continuous">
  <origin rpy="0 0 0" xyz="-0.0014 -0.1437 0.4425"/>
  <parent link="link2"/>
  <child link="link3"/>
  <axis xyz="1.0 0.0048 0.0048"/>
</joint>

<joint name="Rev4" type="continuous">
  <origin rpy="0 0 0" xyz="0.0009 -0.1830 0.0"/>
  <parent link="link3"/>
  <child link="link4"/>
  <axis xyz="0.0048 -1.0 0.0"/>
</joint>

<joint name="Rev5" type="continuous">
  <origin rpy="0 0 0" xyz="0.0007 -0.1515 0.0"/>
  <parent link="link4"/>
  <child link="link5"/>
  <axis xyz="1.0 0.0048 0.0048"/>
</joint>

<joint name="Rev6" type="continuous">
  <origin rpy="0 0 0" xyz="0.0008 -0.0 -0.1735"/>
  <parent link="link5"/>
  <child link="hand"/>
  <axis xyz="0.0048 -0.0 -1.0"/>
</joint>

<joint name="Rev7" type="continuous">
  <origin rpy="0 0 0" xyz="-0.0137 -0.0035 -0.0609"/>
  <parent link="hand"/>
  <child link="finger_r"/>
  <axis xyz="0.0048 -1.0 0.0"/>
</joint>

<joint name="Rev8" type="continuous">
  <origin rpy="0 0 0" xyz="0.0143 -0.0034 -0.0607"/>
  <parent link="hand"/>
  <child link="finger_l"/>
  <axis xyz="0.0048 -1.0 0.0"/>
</joint>

</robot>
