<?xml version="1.0" encoding="utf-8"?>
<robot xmlns:xacro="http://www.ros.org/wiki/xacro" name="hand">
  <!-- safety_distance: Minimum safety distance in [m] by which the collision volumes are expanded and which is enforced during robot motions -->
  <xacro:macro name="hand" params="connected_to:='' ns:='' rpy:='0 0 0' xyz:='0 0 0'">
    <xacro:unless value="${connected_to == ''}">
      <joint name="${ns}_hand_joint" type="fixed">
        <parent link="${connected_to}"/>
        <child link="${ns}_hand"/>
        <origin xyz="${xyz}" rpy="${rpy}"/>
      </joint>
    </xacro:unless>

    <xacro:property name="limit" value="${60 * pi / 180}"/>

    <link name="${ns}_hand">
      <visual>
        <origin rpy="0 0 0" xyz="0 0 0"/>
        <geometry>
          <mesh filename="package://polar_description/meshes/gripper/hand.dae"/>
        </geometry>
      </visual>
      <collision>
        <origin rpy="0 0 0" xyz="0 0 0"/>
        <geometry>
          <mesh filename="package://polar_description/meshes/gripper/hand.dae"/>
        </geometry>
      </collision>
      <inertial>
        <origin rpy="0 0 0" xyz="0.006733 -0.006163 -0.009538"/>
        <mass value="2.3427"/>
        <inertia ixx="0.0028" ixy="0" ixz="-0.0004" iyy="0.0023" iyz="0" izz="0.0035"/>
      </inertial>
    </link>

    <link name="${ns}_outer_l">
      <visual>
        <origin rpy="0 0 0" xyz="-0.040231 0.024653 0.007426"/>
        <geometry>
          <mesh filename="package://polar_description/meshes/gripper/outer_l.dae"/>
        </geometry>
      </visual>
      <collision>
        <origin rpy="0 0 0" xyz="-0.040231 0.024653 0.007426"/>
        <geometry>
          <mesh filename="package://polar_description/meshes/gripper/outer_l.dae"/>
        </geometry>
      </collision>
      <inertial>
        <origin rpy="0 0 0" xyz="0 -0.013601 -0.0020100"/>
        <mass value="0.0589"/>
        <inertia ixx="0" ixy="-0.0" ixz="0.0" iyy="0" iyz="0.0" izz="0"/>
      </inertial>
    </link>

    <link name="${ns}_outer_r">
      <visual>
        <origin rpy="0 0 0" xyz="0.026768 0.024652 0.011626"/>
        <geometry>
          <mesh filename="package://polar_description/meshes/gripper/outer_r.dae"/>
        </geometry>
      </visual>
      <collision>
        <origin rpy="0 0 0" xyz="0.026768 0.024652 0.011626"/>
        <geometry>
          <mesh filename="package://polar_description/meshes/gripper/outer_r.dae"/>
        </geometry>
      </collision>
      <inertial>
        <origin rpy="0 0 0" xyz="0 -0.013627 0.002093"/>
        <mass value="0.058776"/>
        <inertia ixx="0" ixy="-0.0" ixz="-0.0" iyy="0" iyz="0.0" izz="0"/>
      </inertial>
    </link>

    <link name="${ns}_finger_l">
      <visual>
        <origin rpy="0 0 0" xyz="-0.040231 0.069653 0.013526"/>
        <geometry>
          <mesh filename="package://polar_description/meshes/gripper/finger_l.dae"/>
        </geometry>
      </visual>
      <collision>
        <origin rpy="0 0 0" xyz="-0.040231 0.069653 0.013526"/>
        <geometry>
          <mesh filename="package://polar_description/meshes/gripper/finger_l.dae"/>
        </geometry>
      </collision>
      <inertial>
        <origin rpy="0 0 0" xyz="-0.010571 -0.034963 0.004031"/>
        <mass value="0.5436"/>
        <inertia ixx="0.0004" ixy="0" ixz="-0.0" iyy="0.0001" iyz="0" izz="0.0004"/>
      </inertial>
    </link>

    <link name="${ns}_finger_r">
      <visual>
        <origin rpy="0 0 0" xyz="0.026768 0.069652 0.013526"/>
        <geometry>
          <mesh filename="package://polar_description/meshes/gripper/finger_r.dae"/>
        </geometry>
      </visual>
      <collision>
        <origin rpy="0 0 0" xyz="0.026768 0.069652 0.013526"/>
        <geometry>
          <mesh filename="package://polar_description/meshes/gripper/finger_r.dae"/>
        </geometry>
      </collision>
      <inertial>
        <origin rpy="0 0 0" xyz="0.010571 -0.034962 0.003969"/>
        <mass value="0.5436"/>
        <inertia ixx="0.0004" ixy="0" ixz="-0.0" iyy="0.0001" iyz="0" izz="0.0004"/>
      </inertial>
    </link>

    <joint name="${ns}_hand_joint2" type="revolute">
      <origin rpy="0 0 0" xyz="-0.026768 -0.024652 -0.011626"/>
      <parent link="${ns}_hand"/>
      <child link="${ns}_outer_r"/>
      <axis xyz="-0.0 0.0 1.0"/>
      <mimic joint="${ns}_hand_joint1" multiplier="1.0"/>
      <limit effort="100" lower="${-limit}" upper="0" velocity="6.5449"/>
    </joint>

    <joint name="${ns}_hand_joint1" type="revolute">
      <origin rpy="0 0 0" xyz="0.040231 -0.024653 -0.007426"/>
      <parent link="${ns}_hand"/>
      <child link="${ns}_outer_l"/>
      <axis xyz="0.0 -0.0 -1.0"/>
      <limit effort="100" lower="${-limit}" upper="0" velocity="6.5449"/>
    </joint>

    <joint name="${ns}_finger_joint1" type="revolute">
      <origin rpy="0 0 0" xyz="0.0 -0.045 -0.0061"/>
      <parent link="${ns}_outer_l"/>
      <child link="${ns}_finger_l"/>
      <axis xyz="0.0 -0.0 -1.0"/>
      <mimic joint="${ns}_hand_joint1" multiplier="-1.0"/>
      <limit effort="100" lower="0" upper="${limit}" velocity="6.5449"/>
    </joint>

    <joint name="${ns}_finger_joint2" type="revolute">
      <origin rpy="0 0 0" xyz="0.0 -0.045 -0.0019"/>
      <parent link="${ns}_outer_r"/>
      <child link="${ns}_finger_r"/>
      <axis xyz="0.0 -0.0 -1.0"/>
      <mimic joint="${ns}_hand_joint1" multiplier="1.0"/>
      <limit effort="100" lower="${-limit}" upper="0" velocity="6.5449"/>
    </joint>
  </xacro:macro>    
</robot>
