<?xml version="1.0" encoding="utf-8" ?>
<!-- =================================================================================== -->
<!-- |    This document was autogenerated by xacro from /home/hybrayhem/ws_manipulation/src/polar_description/robots/polar_arm_hand.urdf.xacro | -->
<!-- |    EDITING THIS FILE BY HAND IS NOT RECOMMENDED                                 | -->
<!-- =================================================================================== -->
<robot name="polar">
    <link name="world" />
    <joint name="robot_to_world" type="fixed">
        <parent link="world" />
        <child link="polar_link0" />
        <origin rpy="0.0 0.0 0.0" xyz="0.0 0.0 0.0" />
    </joint>
    <link name="polar_link0">
        <visual>
            <origin rpy="0 0 0" xyz="0 0 0" />
            <geometry>
                <mesh filename="package://polar_description/meshes/link0.dae" />
            </geometry>
        </visual>
        <collision>
            <origin rpy="0 0 0" xyz="0 0 0" />
            <geometry>
                <mesh filename="package://polar_description/meshes/link0.dae" />
            </geometry>
        </collision>
        
<inertial>
            <origin rpy="0 0 0" xyz="-0.0003 -0.0 0.0620" />
            <mass value="4.6096" />
            <inertia ixx="0.0098" ixy="0.0" ixz="-0.0" iyy="0.0064" iyz="0.0" izz="0.0145" />
        </inertial>

    </link>
    <link name="polar_link1">
        <visual>
            <origin rpy="0 0 0" xyz="0.0005 0.0 -0.095" />
            <geometry>
                <mesh filename="package://polar_description/meshes/link1.dae" />
            </geometry>
        </visual>
        <collision>
            <origin rpy="0 0 0" xyz="0.0005 0.0 -0.095" />
            <geometry>
                <mesh filename="package://polar_description/meshes/link1.dae" />
            </geometry>
        </collision>
        
<inertial>
            <origin rpy="0 0 0" xyz="-0.0003 0.0414 0.0140" />
            <mass value="5.6966" />
            <inertia ixx="0.0205" ixy="-0.0" ixz="-0.0001" iyy="0.0259" iyz="-0.0012" izz="0.0429" />
        </inertial>

    </link>
    <joint name="polar_joint1" type="revolute">
        <safety_controller k_position="100.0" k_velocity="40.0" soft_lower_limit="-3.76991118431" soft_upper_limit="3.76991118431" />
        <origin rpy="0 0 0" xyz="-0.0005 0.0 0.095" />
        <parent link="polar_link0" />
        <child link="polar_link1" />
        <axis xyz="-0.0048 0.0 1.0" />
        <limit effort="87" lower="-3.76991118431" upper="3.76991118431" velocity="2.1750" />
        <dynamics damping="0.0" friction="0.0" />
    </joint>
    <link name="polar_link2">
        <visual>
            <origin rpy="0 0 0" xyz="0.0001 -0.064 -0.144" />
            <geometry>
                <mesh filename="package://polar_description/meshes/link2.dae" />
            </geometry>
        </visual>
        <collision>
            <origin rpy="0 0 0" xyz="0.0001 -0.064 -0.144" />
            <geometry>
                <mesh filename="package://polar_description/meshes/link2.dae" />
            </geometry>
        </collision>
        
<inertial>
            <origin rpy="0 0 0" xyz="-0.0011 -0.0102 0.2446" />
            <mass value="6.3034" />
            <inertia ixx="0.1301" ixy="-0.0" ixz="0.0003" iyy="0.1119" iyz="0.0241" izz="0.0384" />
        </inertial>

    </link>
    <joint name="polar_joint2" type="revolute">
        <safety_controller k_position="100.0" k_velocity="40.0" soft_lower_limit="-0.96" soft_upper_limit="0.35" />
        <origin rpy="0 0 0" xyz="-0.0005 0.064 0.049" />
        <parent link="polar_link1" />
        <child link="polar_link2" />
        <axis xyz="-1.0 -0.0048 -0.0048" />
        <limit effort="87" lower="-0.96" upper="0.35" velocity="2.1750" />
        <dynamics damping="0.0" friction="0.0" />
    </joint>
    <link name="polar_link3">
        <visual>
            <origin rpy="0 0 0" xyz="0.0024 0.0797 -0.5865" />
            <geometry>
                <mesh filename="package://polar_description/meshes/link3.dae" />
            </geometry>
        </visual>
        <collision>
            <origin rpy="0 0 0" xyz="0.0024 0.0797 -0.5865" />
            <geometry>
                <mesh filename="package://polar_description/meshes/link3.dae" />
            </geometry>
        </collision>
        
<inertial>
            <origin rpy="0 0 0" xyz="0.0002 -0.0607 0.0127" />
            <mass value="2.4044" />
            <inertia ixx="0.0165" ixy="0.0" ixz="0.0" iyy="0.0044" iyz="-0.0028" izz="0.0164" />
        </inertial>

    </link>
    <joint name="polar_joint3" type="revolute">
        <safety_controller k_position="100.0" k_velocity="40.0" soft_lower_limit="-0.26" soft_upper_limit="0.87" />
        <origin rpy="0 0 0" xyz="-0.0014 -0.1437 0.4425" />
        <parent link="polar_link2" />
        <child link="polar_link3" />
        <axis xyz="1.0 0.0048 0.0048" />
        <limit effort="87" lower="-0.26" upper="0.87" velocity="2.1750" />
        <dynamics damping="0.0" friction="0.0" />
    </joint>
    <link name="polar_link4">
        <visual>
            <origin rpy="0 0 0" xyz="0.0016 0.2627 -0.5865" />
            <geometry>
                <mesh filename="package://polar_description/meshes/link4.dae" />
            </geometry>
        </visual>
        <collision>
            <origin rpy="0 0 0" xyz="0.0016 0.2627 -0.5865" />
            <geometry>
                <mesh filename="package://polar_description/meshes/link4.dae" />
            </geometry>
        </collision>
        
<inertial>
            <origin rpy="0 0 0" xyz="0.0004 -0.0779 0.0" />
            <mass value="1.4724" />
            <inertia ixx="0.0052" ixy="0.0" ixz="-0.0" iyy="0.0019" iyz="0.0" izz="0.0059" />
        </inertial>

    </link>
    <joint name="polar_joint4" type="revolute">
        <safety_controller k_position="100.0" k_velocity="40.0" soft_lower_limit="-3.14159265359" soft_upper_limit="3.14159265359" />
        <origin rpy="0 0 0" xyz="0.0009 -0.1830 0.0" />
        <parent link="polar_link3" />
        <child link="polar_link4" />
        <axis xyz="0.0048 -1.0 0.0" />
        <limit effort="87" lower="-3.14159265359" upper="3.14159265359" velocity="2.1750" />
        <dynamics damping="0.0" friction="0.0" />
    </joint>
    <link name="polar_link5">
        <visual>
            <origin rpy="0 0 0" xyz="0.0008 0.4142 -0.5865" />
            <geometry>
                <mesh filename="package://polar_description/meshes/link5.dae" />
            </geometry>
        </visual>
        <collision>
            <origin rpy="0 0 0" xyz="0.0008 0.4142 -0.5865" />
            <geometry>
                <mesh filename="package://polar_description/meshes/link5.dae" />
            </geometry>
        </collision>
        
<inertial>
            <origin rpy="0 0 0" xyz="0.0115 0.0 -0.0568" />
            <mass value="2.2547" />
            <inertia ixx="0.0109" ixy="-0.0" ixz="-0.0014" iyy="0.0136" iyz="-0.0" izz="0.0040" />
        </inertial>

    </link>
    <joint name="polar_joint5" type="revolute">
        <safety_controller k_position="100.0" k_velocity="40.0" soft_lower_limit="-3.14159265359" soft_upper_limit="0.96" />
        <origin rpy="0 0 0" xyz="0.0007 -0.1515 0.0" />
        <parent link="polar_link4" />
        <child link="polar_link5" />
        <axis xyz="1.0 0.0048 0.0048" />
        <limit effort="12" lower="-3.14159265359" upper="0.96" velocity="2.6100" />
        <dynamics damping="0.0" friction="0.0" />
    </joint>
    <link name="polar_link6">
        <visual>
            <origin rpy="0 0 0" xyz="0.0 0.4142 -0.4235" />
            <geometry>
                <mesh filename="package://polar_description/meshes/link6.dae" />
            </geometry>
        </visual>
        <collision>
            <origin rpy="0 0 0" xyz="0.0 0.4142 -0.4235" />
            <geometry>
                <mesh filename="package://polar_description/meshes/link6.dae" />
            </geometry>
        </collision>
        
<inertial>
            <origin rpy="0 0 0" xyz="0.0 0.0 -0.005" />
            <mass value="0.0254" />
            <inertia ixx="0.0" ixy="-0.0" ixz="-0.0" iyy="0.0" iyz="0.0" izz="0.0" />
        </inertial>

    </link>
    <joint name="polar_joint6" type="revolute">
        <safety_controller k_position="100.0" k_velocity="40.0" soft_lower_limit="-3.14159265359" soft_upper_limit="3.14159265359" />
        <origin rpy="0 0 0" xyz="0.0008 -0.0 -0.1630" />
        <parent link="polar_link5" />
        <child link="polar_link6" />
        <axis xyz="0.0048 -0.0 -1.0" />
        <limit effort="12" lower="-3.14159265359" upper="3.14159265359" velocity="2.6100" />
        <dynamics damping="0.0" friction="0.0" />
    </joint>
    <joint name="polar_hand_joint" type="fixed">
        <parent link="polar_link6" />
        <child link="polar_hand" />
        <origin rpy="1.57079632679 0 0" xyz="-0.00675 -0.00964 -0.06152" />
    </joint>
    <link name="polar_hand">
        <visual>
            <origin rpy="0 0 0" xyz="0 0 0" />
            <geometry>
                <mesh filename="package://polar_description/meshes/gripper/hand.dae" />
            </geometry>
        </visual>
        <collision>
            <origin rpy="0 0 0" xyz="0 0 0" />
            <geometry>
                <mesh filename="package://polar_description/meshes/gripper/hand.dae" />
            </geometry>
        </collision>
        
<inertial>
            <origin rpy="0 0 0" xyz="0.006846 0.005366 -0.009625" />
            <mass value="1.2773" />
            <inertia ixx="0.0011" ixy="0.0" ixz="0.0" iyy="0.0006" iyz="0.0" izz="0.0015" />
        </inertial>

    </link>
    <link name="polar_outer_l">
        <visual>
            <origin rpy="0 0 0" xyz="-0.025351 0.027594 0.004951" />
            <geometry>
                <mesh filename="package://polar_description/meshes/gripper/outer_l.dae" />
            </geometry>
        </visual>
        <collision>
            <origin rpy="0 0 0" xyz="-0.025351 0.027594 0.004951" />
            <geometry>
                <mesh filename="package://polar_description/meshes/gripper/outer_l.dae" />
            </geometry>
        </collision>
        
<inertial>
            <origin rpy="0 0 0" xyz="0.006975 -0.006230 -0.004655" />
            <mass value="0.0877" />
            <inertia ixx="0.0" ixy="0.0" ixz="-0.0" iyy="0.0" iyz="0.0" izz="0.0" />
        </inertial>

    </link>
    <link name="polar_outer_r">
        <visual>
            <origin rpy="0 0 0" xyz="0.011889 0.027594 0.004951" />
            <geometry>
                <mesh filename="package://polar_description/meshes/gripper/outer_r.dae" />
            </geometry>
        </visual>
        <collision>
            <origin rpy="0 0 0" xyz="0.011889 0.027594 0.004951" />
            <geometry>
                <mesh filename="package://polar_description/meshes/gripper/outer_r.dae" />
            </geometry>
        </collision>
        
<inertial>
            <origin rpy="0 0 0" xyz="-0.007134 -0.006305 -0.004655" />
            <mass value="0.0868" />
            <inertia ixx="0.0" ixy="0.0" ixz="0.0" iyy="0.0" iyz="-0.0" izz="0.0" />
        </inertial>

    </link>
    <link name="polar_finger_l">
        <visual>
            <origin rpy="0 0 0" xyz="-0.061266 0.066842 0.004951" />
            <geometry>
                <mesh filename="package://polar_description/meshes/gripper/finger_l.dae" />
            </geometry>
        </visual>
        <collision>
            <origin rpy="0 0 0" xyz="-0.061266 0.066842 0.004951" />
            <geometry>
                <mesh filename="package://polar_description/meshes/gripper/finger_l.dae" />
            </geometry>
        </collision>
        
<inertial>
            <origin rpy="0 0 0" xyz="0.006607 -0.028924 -0.004655" />
            <mass value="0.7779" />
            <inertia ixx="0.0009" ixy="0.0" ixz="-0.0" iyy="0.0003" iyz="0.0" izz="0.0009" />
        </inertial>

    </link>
    <link name="polar_finger_r">
        <visual>
            <origin rpy="0 0 0" xyz="0.047804 0.066842 0.004951" />
            <geometry>
                <mesh filename="package://polar_description/meshes/gripper/finger_r.dae" />
            </geometry>
        </visual>
        <collision>
            <origin rpy="0 0 0" xyz="0.047804 0.066842 0.004951" />
            <geometry>
                <mesh filename="package://polar_description/meshes/gripper/finger_r.dae" />
            </geometry>
        </collision>
        
<inertial>
            <origin rpy="0 0 0" xyz="-0.006607 -0.028924 -0.004655" />
            <mass value="0.7779" />
            <inertia ixx="0.0009" ixy="0.0" ixz="0.0" iyy="0.0003" iyz="0.0" izz="0.0009" />
        </inertial>

    </link>
    <joint name="polar_hand_joint2" type="revolute">
        <origin rpy="0 0 0" xyz="-0.011889 -0.027594 -0.004951" />
        <parent link="polar_hand" />
        <child link="polar_outer_r" />
        <axis xyz="0.0 -0.0 -1.0" />
        <mimic joint="polar_hand_joint1" multiplier="-1.0" />
        <limit effort="100" lower="-0.74002" upper="0.827286" velocity="100" />
    </joint>
    <joint name="polar_hand_joint1" type="revolute">
        <origin rpy="0 0 0" xyz="0.025351 -0.027594 -0.004951" />
        <parent link="polar_hand" />
        <child link="polar_outer_l" />
        <axis xyz="0.0 -0.0 -1.0" />
        <limit effort="100" lower="-0.827286" upper="0.74002" velocity="100" />
    </joint>
    <joint name="polar_finger_joint1" type="revolute">
        <origin rpy="0 0 0" xyz="0.035915 -0.039248 0.0" />
        <parent link="polar_outer_l" />
        <child link="polar_finger_l" />
        <axis xyz="-0.0 -0.0 -1.0" />
        <mimic joint="polar_hand_joint1" multiplier="-1.0" />
        <limit effort="100" lower="-0.74002" upper="0.827286" velocity="100" />
    </joint>
    <joint name="polar_finger_joint2" type="revolute">
        <origin rpy="0 0 0" xyz="-0.035915 -0.039248 0.0" />
        <parent link="polar_outer_r" />
        <child link="polar_finger_r" />
        <axis xyz="0.0 0.0 1.0" />
        <mimic joint="polar_hand_joint1" multiplier="-1.0" />
        <limit effort="100" lower="-0.74002" upper="0.827286" velocity="100" />
    </joint>
    <!-- Link0 -->
    <gazebo reference="polar_link0">
        <material>Gazebo/Grey</material>
        <mu1>0.2</mu1>
        <mu2>0.2</mu2>
    </gazebo>
    <!-- Link1 -->
    <gazebo reference="polar_link1">
        <material>Gazebo/White</material>
        <mu1>0.2</mu1>
        <mu2>0.2</mu2>
    </gazebo>
    <!-- Link2 -->
    <gazebo reference="polar_link2">
        <material>Gazebo/White</material>
        <mu1>0.2</mu1>
        <mu2>0.2</mu2>
    </gazebo>
    <!-- Link3 -->
    <gazebo reference="polar_link3">
        <material>Gazebo/White</material>
        <mu1>0.2</mu1>
        <mu2>0.2</mu2>
    </gazebo>
    <!-- Link4 -->
    <gazebo reference="polar_link4">
        <material>Gazebo/White</material>
        <mu1>0.2</mu1>
        <mu2>0.2</mu2>
    </gazebo>
    <!-- Link5 -->
    <gazebo reference="polar_link5">
        <material>Gazebo/White</material>
        <mu1>0.2</mu1>
        <mu2>0.2</mu2>
    </gazebo>
    <!-- Link6 -->
    <gazebo reference="polar_link6">
        <material>Gazebo/White</material>
        <mu1>0.2</mu1>
        <mu2>0.2</mu2>
    </gazebo>
    <!-- LinkLeftOuter -->
    <gazebo reference="polar_outer_l">
        <material>Gazebo/Grey</material>
        <mu1>0.2</mu1>
        <mu2>0.2</mu2>
    </gazebo>
    <!-- LinkRightOuter -->
    <gazebo reference="polar_outer_r">
        <material>Gazebo/Grey</material>
        <mu1>0.2</mu1>
        <mu2>0.2</mu2>
    </gazebo>
    <!-- LinkLeftFinger -->
    <gazebo reference="polar_finger_l">
        <material>Gazebo/Grey</material>
        <mu1>0.2</mu1>
        <mu2>0.2</mu2>
    </gazebo>
    <!-- LinkRightFinger-->
    <gazebo reference="polar_finger_r">
        <material>Gazebo/Grey</material>
        <mu1>0.2</mu1>
        <mu2>0.2</mu2>
    </gazebo>
    <!-- Load Gazebo lib and set the robot namespace -->
    <gazebo>
        <plugin filename="libgazebo_ros_control.so" name="gazebo_ros_control">
            <robotNamespace>/polar</robotNamespace>
        </plugin>
    </gazebo>
    <!-- Polar arm -->
    
<transmission name="polar_tran_1">
        <type>transmission_interface/SimpleTransmission</type>
        <joint name="polar_joint1">
            <hardwareInterface>hardware_interface/PositionJointInterface</hardwareInterface>
        </joint>
        <actuator name="polar_motor_1">
            <hardwareInterface>hardware_interface/PositionJointInterface</hardwareInterface>
            <mechanicalReduction>1</mechanicalReduction>
        </actuator>
    </transmission>
    <transmission name="polar_tran_2">
        <type>transmission_interface/SimpleTransmission</type>
        <joint name="polar_joint2">
            <hardwareInterface>hardware_interface/PositionJointInterface</hardwareInterface>
        </joint>
        <actuator name="polar_motor_2">
            <hardwareInterface>hardware_interface/PositionJointInterface</hardwareInterface>
            <mechanicalReduction>1</mechanicalReduction>
        </actuator>
    </transmission>
    <transmission name="polar_tran_3">
        <type>transmission_interface/SimpleTransmission</type>
        <joint name="polar_joint3">
            <hardwareInterface>hardware_interface/PositionJointInterface</hardwareInterface>
        </joint>
        <actuator name="polar_motor_3">
            <hardwareInterface>hardware_interface/PositionJointInterface</hardwareInterface>
            <mechanicalReduction>1</mechanicalReduction>
        </actuator>
    </transmission>
    <transmission name="polar_tran_4">
        <type>transmission_interface/SimpleTransmission</type>
        <joint name="polar_joint4">
            <hardwareInterface>hardware_interface/PositionJointInterface</hardwareInterface>
        </joint>
        <actuator name="polar_motor_4">
            <hardwareInterface>hardware_interface/PositionJointInterface</hardwareInterface>
            <mechanicalReduction>1</mechanicalReduction>
        </actuator>
    </transmission>
    <transmission name="polar_tran_5">
        <type>transmission_interface/SimpleTransmission</type>
        <joint name="polar_joint5">
            <hardwareInterface>hardware_interface/PositionJointInterface</hardwareInterface>
        </joint>
        <actuator name="polar_motor_5">
            <hardwareInterface>hardware_interface/PositionJointInterface</hardwareInterface>
            <mechanicalReduction>1</mechanicalReduction>
        </actuator>
    </transmission>
    <transmission name="polar_tran_6">
        <type>transmission_interface/SimpleTransmission</type>
        <joint name="polar_joint6">
            <hardwareInterface>hardware_interface/PositionJointInterface</hardwareInterface>
        </joint>
        <actuator name="polar_motor_6">
            <hardwareInterface>hardware_interface/PositionJointInterface</hardwareInterface>
            <mechanicalReduction>1</mechanicalReduction>
        </actuator>
    </transmission>
    <!-- Hand -->
    <transmission name="polar_hand_tran">
        <type>transmission_interface/SimpleTransmission</type>
        <joint name="polar_hand_joint1">
            <hardwareInterface>hardware_interface/PositionJointInterface</hardwareInterface>
        </joint>
        <actuator name="polar_hand_motor_1">
            <hardwareInterface>hardware_interface/PositionJointInterface</hardwareInterface>
            <mechanicalReduction>1</mechanicalReduction>
        </actuator>
    </transmission>
    <!-- Mimic joints -->
    <gazebo>
        <plugin filename="libgazebo_mimic_joint_plugin.so" name="polar_hand_mimic_1">
            <joint>polar_hand_joint2</joint>
            <mimicJoint>polar_hand_joint1</mimicJoint>
            <multiplier>-1.0</multiplier>
            <offset>0.0</offset>
        </plugin>
        <plugin filename="libgazebo_mimic_joint_plugin.so" name="polar_hand_mimic_2">
            <joint>polar_finger_joint1</joint>
            <mimicJoint>polar_hand_joint1</mimicJoint>
            <multiplier>-1.0</multiplier>
            <offset>0.0</offset>
        </plugin>
        <plugin filename="libgazebo_mimic_joint_plugin.so" name="polar_hand_mimic_3">
            <joint>polar_finger_joint2</joint>
            <mimicJoint>polar_hand_joint1</mimicJoint>
            <multiplier>-1.0</multiplier>
            <offset>0.0</offset>
        </plugin>
    </gazebo>
    <transmission name="trans_polar_joint1">
        <type>transmission_interface/SimpleTransmission</type>
        <joint name="polar_joint1">
            <hardwareInterface>hardware_interface/EffortJointInterface</hardwareInterface>
        </joint>
        <actuator name="polar_joint1_motor">
            <hardwareInterface>hardware_interface/EffortJointInterface</hardwareInterface>
            <mechanicalReduction>1</mechanicalReduction>
        </actuator>
    </transmission>
    <transmission name="trans_polar_joint2">
        <type>transmission_interface/SimpleTransmission</type>
        <joint name="polar_joint2">
            <hardwareInterface>hardware_interface/EffortJointInterface</hardwareInterface>
        </joint>
        <actuator name="polar_joint2_motor">
            <hardwareInterface>hardware_interface/EffortJointInterface</hardwareInterface>
            <mechanicalReduction>1</mechanicalReduction>
        </actuator>
    </transmission>
    <transmission name="trans_polar_joint3">
        <type>transmission_interface/SimpleTransmission</type>
        <joint name="polar_joint3">
            <hardwareInterface>hardware_interface/EffortJointInterface</hardwareInterface>
        </joint>
        <actuator name="polar_joint3_motor">
            <hardwareInterface>hardware_interface/EffortJointInterface</hardwareInterface>
            <mechanicalReduction>1</mechanicalReduction>
        </actuator>
    </transmission>
    <transmission name="trans_polar_joint4">
        <type>transmission_interface/SimpleTransmission</type>
        <joint name="polar_joint4">
            <hardwareInterface>hardware_interface/EffortJointInterface</hardwareInterface>
        </joint>
        <actuator name="polar_joint4_motor">
            <hardwareInterface>hardware_interface/EffortJointInterface</hardwareInterface>
            <mechanicalReduction>1</mechanicalReduction>
        </actuator>
    </transmission>
    <transmission name="trans_polar_joint5">
        <type>transmission_interface/SimpleTransmission</type>
        <joint name="polar_joint5">
            <hardwareInterface>hardware_interface/EffortJointInterface</hardwareInterface>
        </joint>
        <actuator name="polar_joint5_motor">
            <hardwareInterface>hardware_interface/EffortJointInterface</hardwareInterface>
            <mechanicalReduction>1</mechanicalReduction>
        </actuator>
    </transmission>
    <transmission name="trans_polar_joint6">
        <type>transmission_interface/SimpleTransmission</type>
        <joint name="polar_joint6">
            <hardwareInterface>hardware_interface/EffortJointInterface</hardwareInterface>
        </joint>
        <actuator name="polar_joint6_motor">
            <hardwareInterface>hardware_interface/EffortJointInterface</hardwareInterface>
            <mechanicalReduction>1</mechanicalReduction>
        </actuator>
    </transmission>
    <transmission name="trans_polar_hand_joint2">
        <type>transmission_interface/SimpleTransmission</type>
        <joint name="polar_hand_joint2">
            <hardwareInterface>hardware_interface/EffortJointInterface</hardwareInterface>
        </joint>
        <actuator name="polar_hand_joint2_motor">
            <hardwareInterface>hardware_interface/EffortJointInterface</hardwareInterface>
            <mechanicalReduction>1</mechanicalReduction>
        </actuator>
    </transmission>
    <transmission name="trans_polar_hand_joint1">
        <type>transmission_interface/SimpleTransmission</type>
        <joint name="polar_hand_joint1">
            <hardwareInterface>hardware_interface/EffortJointInterface</hardwareInterface>
        </joint>
        <actuator name="polar_hand_joint1_motor">
            <hardwareInterface>hardware_interface/EffortJointInterface</hardwareInterface>
            <mechanicalReduction>1</mechanicalReduction>
        </actuator>
    </transmission>
    <transmission name="trans_polar_finger_joint1">
        <type>transmission_interface/SimpleTransmission</type>
        <joint name="polar_finger_joint1">
            <hardwareInterface>hardware_interface/EffortJointInterface</hardwareInterface>
        </joint>
        <actuator name="polar_finger_joint1_motor">
            <hardwareInterface>hardware_interface/EffortJointInterface</hardwareInterface>
            <mechanicalReduction>1</mechanicalReduction>
        </actuator>
    </transmission>
    <transmission name="trans_polar_finger_joint2">
        <type>transmission_interface/SimpleTransmission</type>
        <joint name="polar_finger_joint2">
            <hardwareInterface>hardware_interface/EffortJointInterface</hardwareInterface>
        </joint>
        <actuator name="polar_finger_joint2_motor">
            <hardwareInterface>hardware_interface/EffortJointInterface</hardwareInterface>
            <mechanicalReduction>1</mechanicalReduction>
        </actuator>
    </transmission>
    <gazebo>
        <plugin name="gazebo_ros_control" filename="libgazebo_ros_control.so">
            <robotNamespace>/</robotNamespace>
        </plugin>
    </gazebo>
</robot>