<?xml version='1.0' encoding='utf-8'?>
<robot xmlns:xacro="http://www.ros.org/wiki/xacro" name="polar">
  <!-- safety_distance: Minimum safety distance in [m] by which the collision volumes are expanded and which is enforced during robot motions -->
  <!-- arm_id: Namespace of the polar arm. Serves to differentiate between arms in case of multiple instances. -->
  <xacro:macro name="polar_arm" params="arm_id:='polar' description_pkg:='polar_description' connected_to:='' xyz:='0 0 0' rpy:='0 0 0'">
    <xacro:unless value="${not connected_to}">
      <joint name="${arm_id}_joint_${connected_to}" type="fixed">
        <parent link="${connected_to}"/>
        <child link="${arm_id}_link0"/>
        <origin rpy="${rpy}" xyz="${xyz}"/>
      </joint>
    </xacro:unless>

    <xacro:property name="joint_damping" value="0.0"/>
    <xacro:property name="joint_friction" value="0.0"/>
    <xacro:property name="safety_k_position" value="100.0"/>
    <xacro:property name="safety_k_velocity" value="40.0"/>

    <link name="world" />
    <joint name="robot_to_world" type="fixed">
      <parent link="world" />
      <child link="${arm_id}_link0" />
      <origin xyz="0.0 0.0 0.0" rpy="0.0 0.0 0.0" />
    </joint>

    <link name="${arm_id}_link0">
      <visual>
        <origin rpy="0 0 0" xyz="0 0 0"/>
        <geometry>
          <mesh filename="package://${description_pkg}/meshes/link0.dae"/>
        </geometry>
      </visual>
      <collision>
        <origin rpy="0 0 0" xyz="0 0 0"/>
        <geometry>
          <mesh filename="package://${description_pkg}/meshes/link0.dae"/>
        </geometry>
      </collision>
      <inertial>
        <origin rpy="0 0 0" xyz="-0.0003 -0.0 0.0620"/>
        <mass value="4.6096"/>
        <inertia ixx="0.0098" ixy="0.0" ixz="-0.0" iyy="0.0064" iyz="0.0" izz="0.0145"/>
      </inertial>
    </link>

    <link name="${arm_id}_link1">
      <visual>
        <origin rpy="0 0 0" xyz="0.0005 0.0 -0.095"/>
        <geometry>
          <mesh filename="package://${description_pkg}/meshes/link1.dae"/>
        </geometry>
      </visual>
      <collision>
        <origin rpy="0 0 0" xyz="0.0005 0.0 -0.095"/>
        <geometry>
          <mesh filename="package://${description_pkg}/meshes/link1.dae"/>
        </geometry>
      </collision>
      <inertial>
        <origin rpy="0 0 0" xyz="-0.0003 0.0414 0.0140"/>
        <mass value="5.6966"/>
        <inertia ixx="0.0205" ixy="-0.0" ixz="-0.0001" iyy="0.0259" iyz="-0.0012" izz="0.0429"/>
      </inertial>
    </link>
    <joint name="${arm_id}_joint1" type="revolute">
      <safety_controller k_position="${safety_k_position}" k_velocity="${safety_k_velocity}" soft_lower_limit="${-1.2*pi}" soft_upper_limit="${1.2*pi}"/>
      <origin rpy="0 0 0" xyz="-0.0005 0.0 0.095"/>
      <parent link="${arm_id}_link0"/>
      <child link="${arm_id}_link1"/>
      <axis xyz="-0.0048 0.0 1.0"/>
      <limit effort="87" lower="${-1.2*pi}" upper="${1.2*pi}" velocity="2.1750"/>
      <dynamics damping="${joint_damping}" friction="${joint_friction}"/>
    </joint>

    <link name="${arm_id}_link2">
      <visual>
        <origin rpy="0 0 0" xyz="0.0001 -0.064 -0.144"/>
        <geometry>
          <mesh filename="package://${description_pkg}/meshes/link2.dae"/>
        </geometry>
      </visual>
      <collision>
        <origin rpy="0 0 0" xyz="0.0001 -0.064 -0.144"/>
        <geometry>
          <mesh filename="package://${description_pkg}/meshes/link2.dae"/>
        </geometry>
      </collision>
      <inertial>
        <origin rpy="0 0 0" xyz="-0.0011 -0.0102 0.2446"/>
        <mass value="6.3034"/>
        <inertia ixx="0.1301" ixy="-0.0" ixz="0.0003" iyy="0.1119" iyz="0.0241" izz="0.0384"/>
      </inertial>
    </link>
    <joint name="${arm_id}_joint2" type="revolute">
      <safety_controller k_position="${safety_k_position}" k_velocity="${safety_k_velocity}" soft_lower_limit="-0.96" soft_upper_limit="0.35"/>
      <origin rpy="0 0 0" xyz="-0.0005 0.064 0.049"/>
      <parent link="${arm_id}_link1"/>
      <child link="${arm_id}_link2"/>
      <axis xyz="-1.0 -0.0048 -0.0048"/>
      <limit effort="87" lower="-0.96" upper="0.35" velocity="2.1750"/>
      <dynamics damping="${joint_damping}" friction="${joint_friction}"/>
    </joint>

    <link name="${arm_id}_link3">
      <visual>
        <origin rpy="0 0 0" xyz="0.0024 0.0797 -0.5865"/>
        <geometry>
          <mesh filename="package://${description_pkg}/meshes/link3.dae"/>
        </geometry>
      </visual>
      <collision>
        <origin rpy="0 0 0" xyz="0.0024 0.0797 -0.5865"/>
        <geometry>
          <mesh filename="package://${description_pkg}/meshes/link3.dae"/>
        </geometry>
      </collision>
      <inertial>
        <origin rpy="0 0 0" xyz="0.0002 -0.0607 0.0127"/>
        <mass value="2.4044"/>
        <inertia ixx="0.0165" ixy="0.0" ixz="0.0" iyy="0.0044" iyz="-0.0028" izz="0.0164"/>
      </inertial>
    </link>
    <joint name="${arm_id}_joint3" type="revolute">
      <safety_controller k_position="${safety_k_position}" k_velocity="${safety_k_velocity}" soft_lower_limit="-0.26" soft_upper_limit="0.87"/>
      <origin rpy="0 0 0" xyz="-0.0014 -0.1437 0.4425"/>
      <parent link="${arm_id}_link2"/>
      <child link="${arm_id}_link3"/>
      <axis xyz="1.0 0.0048 0.0048"/>
      <limit effort="87" lower="-0.26" upper="0.87" velocity="2.1750"/>
      <dynamics damping="${joint_damping}" friction="${joint_friction}"/>
    </joint>

    <link name="${arm_id}_link4">
      <visual>
        <origin rpy="0 0 0" xyz="0.0016 0.2627 -0.5865"/>
        <geometry>
          <mesh filename="package://${description_pkg}/meshes/link4.dae"/>
        </geometry>
      </visual>
      <collision>
        <origin rpy="0 0 0" xyz="0.0016 0.2627 -0.5865"/>
        <geometry>
          <mesh filename="package://${description_pkg}/meshes/link4.dae"/>
        </geometry>
      </collision>
      <inertial>
        <origin rpy="0 0 0" xyz="0.0004 -0.0779 0.0"/>
        <mass value="1.4724"/>
        <inertia ixx="0.0052" ixy="0.0" ixz="-0.0" iyy="0.0019" iyz="0.0" izz="0.0059"/>
      </inertial>
    </link>
    <joint name="${arm_id}_joint4" type="revolute">
      <safety_controller k_position="${safety_k_position}" k_velocity="${safety_k_velocity}" soft_lower_limit="${-pi}" soft_upper_limit="${pi}"/>
      <origin rpy="0 0 0" xyz="0.0009 -0.1830 0.0"/>
      <parent link="${arm_id}_link3"/>
      <child link="${arm_id}_link4"/>
      <axis xyz="0.0048 -1.0 0.0"/>
      <limit effort="87" lower="${-pi}" upper="${pi}" velocity="2.1750"/>
      <dynamics damping="${joint_damping}" friction="${joint_friction}"/>
    </joint>

    <link name="${arm_id}_link5">
      <visual>
        <origin rpy="0 0 0" xyz="0.0008 0.4142 -0.5865"/>
        <geometry>
          <mesh filename="package://${description_pkg}/meshes/link5.dae"/>
        </geometry>
      </visual>
      <collision>
        <origin rpy="0 0 0" xyz="0.0008 0.4142 -0.5865"/>
        <geometry>
          <mesh filename="package://${description_pkg}/meshes/link5.dae"/>
        </geometry>
      </collision>
      <inertial>
        <origin rpy="0 0 0" xyz="0.0115 0.0 -0.0568"/>
        <mass value="2.2547"/>
        <inertia ixx="0.0109" ixy="-0.0" ixz="-0.0014" iyy="0.0136" iyz="-0.0" izz="0.0040"/>
      </inertial>
    </link>
    <joint name="${arm_id}_joint5" type="revolute">
      <safety_controller k_position="${safety_k_position}" k_velocity="${safety_k_velocity}" soft_lower_limit="${-pi}" soft_upper_limit="0.96"/>
      <origin rpy="0 0 0" xyz="0.0007 -0.1515 0.0"/>
      <parent link="${arm_id}_link4"/>
      <child link="${arm_id}_link5"/>
      <axis xyz="1.0 0.0048 0.0048"/>
      <limit effort="12" lower="${-pi}" upper="0.96" velocity="2.6100"/>
      <dynamics damping="${joint_damping}" friction="${joint_friction}"/>
    </joint>

    <link name="${arm_id}_link6">
      <visual>
        <origin rpy="0 0 0" xyz="0.0 0.4142 -0.4235"/>
        <geometry>
          <mesh filename="package://${description_pkg}/meshes/link6.dae"/>
        </geometry>
      </visual>
      <collision>
        <origin rpy="0 0 0" xyz="0.0 0.4142 -0.4235"/>
        <geometry>
          <mesh filename="package://${description_pkg}/meshes/link6.dae"/>
        </geometry>
      </collision>
      <inertial>
        <origin rpy="0 0 0" xyz="0.0 0.0 -0.005"/>
        <mass value="0.0254"/>
        <inertia ixx="0.0" ixy="-0.0" ixz="-0.0" iyy="0.0" iyz="0.0" izz="0.0"/>
      </inertial>
    </link>
    <joint name="${arm_id}_joint6" type="revolute">
      <safety_controller k_position="${safety_k_position}" k_velocity="${safety_k_velocity}" soft_lower_limit="${-pi}" soft_upper_limit="${pi}"/>
      <origin rpy="0 0 0" xyz="0.0008 -0.0 -0.1630"/>
      <parent link="${arm_id}_link5"/>
      <child link="${arm_id}_link6"/>
      <axis xyz="0.0048 -0.0 -1.0"/>
      <limit effort="12" lower="${-pi}" upper="${pi}" velocity="2.6100"/>
      <dynamics damping="${joint_damping}" friction="${joint_friction}"/>
    </joint>

  </xacro:macro>
</robot>
